Workbook
Name bacterialConc: Table22[bacterialConcX]
Name bacterialStrain: Table9[bacterialStrain]
Name bacterialTreatment: Table7[bacterialTreatment]
Name bacterialVolUnit: Table11[bacterialVolUnit]
Name compCASRN: Table6[compCASRN]
Name compDelivery: Table15[compDelivery]
Name compName: Table6[compName]
Name compUnit: Table16[compUnit]
Name compVehicle: Table19[compVehicle]
Name Drop: Table55[[#Headers],[dropCode]]
Name DropCode: #REF!
Name Drops: Table55[[#All],[dropCode]]
Name dropSign: #REF!
Name elegansStrain: Table8[elegansStrain]
Name expName: expLookup!$M:$M
Name expReplicate: Table5[expReplicate]
Name expResearcher: Table10[expResearcher]
Name expType: Table4[expType]
Name expUnit: Table12[expUnit]
Name incubateIncubator: Table25[incubateTemperature]
Name incubateO2: Table23[incubateO2]
Name incubationMethod: Table14[incubationMethod]
Name incubationUnit: Table13[incubationUnit]
Name incubationVial: Table17[incubationVial]
Name plateColumn: Table2[plateColumn]
Name plateRow: Table1[plateRow]
Name TEST2: Table56[[#All],[TEST2]]
Name vialNr: Table24[vialNr]

Sheet expParameters
A1: plateRow | B1: plateColumn | C1: vialNr | D1: dropCode | E1: expType | F1: expReplicate | G1: expName | H1: expDate | I1: expResearcher | J1: expTime | K1: expUnit | L1: expVolumeCounted | M1: RawData | N1: compCASRN | O1: compName | P1: compConcentration | Q1: compUnit | R1: compDelivery | S1: compVehicle | T1: elegansStrain | U1: elegansInput | V1: bacterialStrain | W1: bacterialTreatment | X1: bacterialOD600 | Y1: bacterialConcX | Z1: bacterialVolume | AA1: bacterialVolUnit | AB1: incubationVial | AC1: incubationVolume | AD1: incubationUnit | AE1: incubationMethod | AF1: incubationRPM | AG1: bubble | AH1: incubateTemperature
C2: 1 | D2: a | E2: experiment | F2: 3 | G2: CE.LIQ.FLOW.062 | H2: 44165 | I2: Sergio Reijnders - Ellis Herder | J2: 68 | K2: hour | L2: 50 | M2: 44 | N2: 24157-81-1 | O2: =VLOOKUP(Table3[[#This Row],[compCASRN]],expLookup!S:T,2,FALSE) -> 2,6-diisopropylnaphthalene | P2: 4.99 | Q2: nM | R2: Liquid | S2: controlVehicleA | T2: N2 | U2: 25 | V2: OP50 | W2: heated | X2: 0.743 | Y2: 8 | Z2: 300 | AA2: ul | AB2: 1,5 glass vial | AC2: 1000 | AD2: ul | AE2: rockroll | AF2: 35 | AG2: #N/A | AH2: 20
C3: 1 | D3: b | E3: experiment | F3: 3 | G3: CE.LIQ.FLOW.062 | H3: 44165 | I3: Sergio Reijnders - Ellis Herder | J3: 68 | K3: hour | L3: 50 | M3: 37 | N3: 24157-81-1 | O3: =VLOOKUP(Table3[[#This Row],[compCASRN]],expLookup!S:T,2,FALSE) -> 2,6-diisopropylnaphthalene | P3: 4.99 | Q3: nM | R3: Liquid | S3: controlVehicleA | T3: N2 | U3: 25 | V3: OP50 | W3: heated | X3: 0.743 | Y3: 8 | Z3: 300 | AA3: ul | AB3: 1,5 glass vial | AC3: 1000 | AD3: ul | AE3: rockroll | AF3: 35 | AG3: #N/A | AH3: 20
C4: 1 | D4: c | E4: experiment | F4: 3 | G4: CE.LIQ.FLOW.062 | H4: 44165 | I4: Sergio Reijnders - Ellis Herder | J4: 68 | K4: hour | L4: 50 | M4: 45 | N4: 24157-81-1 | O4: =VLOOKUP(Table3[[#This Row],[compCASRN]],expLookup!S:T,2,FALSE) -> 2,6-diisopropylnaphthalene | P4: 4.99 | Q4: nM | R4: Liquid | S4: controlVehicleA | T4: N2 | U4: 25 | V4: OP50 | W4: heated | X4: 0.743 | Y4: 8 | Z4: 300 | AA4: ul | AB4: 1,5 glass vial | AC4: 1000 | AD4: ul | AE4: rockroll | AF4: 35 | AG4: #N/A | AH4: 20
C5: 1 | D5: d | E5: experiment | F5: 3 | G5: CE.LIQ.FLOW.062 | H5: 44165 | I5: Sergio Reijnders - Ellis Herder | J5: 68 | K5: hour | L5: 50 | M5: 47 | N5: 24157-81-1 | O5: =VLOOKUP(Table3[[#This Row],[compCASRN]],expLookup!S:T,2,FALSE) -> 2,6-diisopropylnaphthalene | P5: 4.99 | Q5: nM | R5: Liquid | S5: controlVehicleA | T5: N2 | U5: 25 | V5: OP50 | W5: heated | X5: 0.743 | Y5: 8 | Z5: 300 | AA5: ul | AB5: 1,5 glass vial | AC5: 1000 | AD5: ul | AE5: rockroll | AF5: 35 | AG5: #N/A | AH5: 20
C6: 1 | D6: e | E6: experiment | F6: 3 | G6: CE.LIQ.FLOW.062 | H6: 44165 | I6: Sergio Reijnders - Ellis Herder | J6: 68 | K6: hour | L6: 50 | M6: 41 | N6: 24157-81-1 | O6: =VLOOKUP(Table3[[#This Row],[compCASRN]],expLookup!S:T,2,FALSE) -> 2,6-diisopropylnaphthalene | P6: 4.99 | Q6: nM | R6: Liquid | S6: controlVehicleA | T6: N2 | U6: 25 | V6: OP50 | W6: heated | X6: 0.743 | Y6: 8 | Z6: 300 | AA6: ul | AB6: 1,5 glass vial | AC6: 1000 | AD6: ul | AE6: rockroll | AF6: 35 | AG6: #N/A | AH6: 20
C7: 2 | D7: a | E7: experiment | F7: 3 | G7: CE.LIQ.FLOW.062 | H7: 44165 | I7: Sergio Reijnders - Ellis Herder | J7: 68 | K7: hour | L7: 50 | M7: 35 | N7: 24157-81-1 | O7: =VLOOKUP(Table3[[#This Row],[compCASRN]],expLookup!S:T,2,FALSE) -> 2,6-diisopropylnaphthalene | P7: 4.99 | Q7: nM | R7: Liquid | S7: controlVehicleA | T7: N2 | U7: 25 | V7: OP50 | W7: heated | X7: 0.743 | Y7: 8 | Z7: 300 | AA7: ul | AB7: 1,5 glass vial | AC7: 1000 | AD7: ul | AE7: rockroll | AF7: 35 | AG7: #N/A | AH7: 20
C8: 2 | D8: b | E8: experiment | F8: 3 | G8: CE.LIQ.FLOW.062 | H8: 44165 | I8: Sergio Reijnders - Ellis Herder | J8: 68 | K8: hour | L8: 50 | M8: 41 | N8: 24157-81-1 | O8: =VLOOKUP(Table3[[#This Row],[compCASRN]],expLookup!S:T,2,FALSE) -> 2,6-diisopropylnaphthalene | P8: 4.99 | Q8: nM | R8: Liquid | S8: controlVehicleA | T8: N2 | U8: 25 | V8: OP50 | W8: heated | X8: 0.743 | Y8: 8 | Z8: 300 | AA8: ul | AB8: 1,5 glass vial | AC8: 1000 | AD8: ul | AE8: rockroll | AF8: 35 | AG8: #N/A | AH8: 20
C9: 2 | D9: c | E9: experiment | F9: 3 | G9: CE.LIQ.FLOW.062 | H9: 44165 | I9: Sergio Reijnders - Ellis Herder | J9: 68 | K9: hour | L9: 50 | M9: 36 | N9: 24157-81-1 | O9: =VLOOKUP(Table3[[#This Row],[compCASRN]],expLookup!S:T,2,FALSE) -> 2,6-diisopropylnaphthalene | P9: 4.99 | Q9: nM | R9: Liquid | S9: controlVehicleA | T9: N2 | U9: 25 | V9: OP50 | W9: heated | X9: 0.743 | Y9: 8 | Z9: 300 | AA9: ul | AB9: 1,5 glass vial | AC9: 1000 | AD9: ul | AE9: rockroll | AF9: 35 | AG9: #N/A | AH9: 20
C10: 2 | D10: d | E10: experiment | F10: 3 | G10: CE.LIQ.FLOW.062 | H10: 44165 | I10: Sergio Reijnders - Ellis Herder | J10: 68 | K10: hour | L10: 50 | M10: 40 | N10: 24157-81-1 | O10: =VLOOKUP(Table3[[#This Row],[compCASRN]],expLookup!S:T,2,FALSE) -> 2,6-diisopropylnaphthalene | P10: 4.99 | Q10: nM | R10: Liquid | S10: controlVehicleA | T10: N2 | U10: 25 | V10: OP50 | W10: heated | X10: 0.743 | Y10: 8 | Z10: 300 | AA10: ul | AB10: 1,5 glass vial | AC10: 1000 | AD10: ul | AE10: rockroll | AF10: 35 | AG10: #N/A | AH10: 20
C11: 2 | D11: e | E11: experiment | F11: 3 | G11: CE.LIQ.FLOW.062 | H11: 44165 | I11: Sergio Reijnders - Ellis Herder | J11: 68 | K11: hour | L11: 50 | M11: 38 | N11: 24157-81-1 | O11: =VLOOKUP(Table3[[#This Row],[compCASRN]],expLookup!S:T,2,FALSE) -> 2,6-diisopropylnaphthalene | P11: 4.99 | Q11: nM | R11: Liquid | S11: controlVehicleA | T11: N2 | U11: 25 | V11: OP50 | W11: heated | X11: 0.743 | Y11: 8 | Z11: 300 | AA11: ul | AB11: 1,5 glass vial | AC11: 1000 | AD11: ul | AE11: rockroll | AF11: 35 | AG11: #N/A | AH11: 20
C12: 3 | D12: a | E12: experiment | F12: 3 | G12: CE.LIQ.FLOW.062 | H12: 44165 | I12: Sergio Reijnders - Ellis Herder | J12: 68 | K12: hour | L12: 50 | M12: 44 | N12: 24157-81-1 | O12: =VLOOKUP(Table3[[#This Row],[compCASRN]],expLookup!S:T,2,FALSE) -> 2,6-diisopropylnaphthalene | P12: 4.99 | Q12: nM | R12: Liquid | S12: controlVehicleA | T12: N2 | U12: 25 | V12: OP50 | W12: heated | X12: 0.743 | Y12: 8 | Z12: 300 | AA12: ul | AB12: 1,5 glass vial | AC12: 1000 | AD12: ul | AE12: rockroll | AF12: 35 | AG12: #N/A | AH12: 20
C13: 3 | D13: b | E13: experiment | F13: 3 | G13: CE.LIQ.FLOW.062 | H13: 44165 | I13: Sergio Reijnders - Ellis Herder | J13: 68 | K13: hour | L13: 50 | M13: 48 | N13: 24157-81-1 | O13: =VLOOKUP(Table3[[#This Row],[compCASRN]],expLookup!S:T,2,FALSE) -> 2,6-diisopropylnaphthalene | P13: 4.99 | Q13: nM | R13: Liquid | S13: controlVehicleA | T13: N2 | U13: 25 | V13: OP50 | W13: heated | X13: 0.743 | Y13: 8 | Z13: 300 | AA13: ul | AB13: 1,5 glass vial | AC13: 1000 | AD13: ul | AE13: rockroll | AF13: 35 | AG13: #N/A | AH13: 20
... C191: 2 | D191: e | E191: experiment | F191: 3 | G191: CE.LIQ.FLOW.062 | H191: 44165 | I191: Sergio Reijnders - Ellis Herder | J191: 68 | K191: hour | L191: 50 | M191: 1 | N191: 91-20-3 | O191: =VLOOKUP(Table3[[#This Row],[compCASRN]],expLookup!S:T,2,FALSE) -> naphthalene | P191: 19.5 | Q191: nM | R191: Liquid | S191: controlVehicleA | T191: N2 | U191: 25 | V191: OP50 | W191: heated | X191: 0.743 | Y191: 8 | Z191: 300 | AA191: ul | AB191: 1,5 glass vial | AC191: 1000 | AD191: ul | AE191: rockroll | AF191: 35 | AG191: #N/A | AH191: 20
C192: 3 | D192: a | E192: experiment | F192: 3 | G192: CE.LIQ.FLOW.062 | H192: 44165 | I192: Sergio Reijnders - Ellis Herder | J192: 68 | K192: hour | L192: 50 | N192: 91-20-3 | O192: =VLOOKUP(Table3[[#This Row],[compCASRN]],expLookup!S:T,2,FALSE) -> naphthalene | P192: 19.5 | Q192: nM | R192: Liquid | S192: controlVehicleA | T192: N2 | U192: 25 | V192: OP50 | W192: heated | X192: 0.743 | Y192: 8 | Z192: 300 | AA192: ul | AB192: 1,5 glass vial | AC192: 1000 | AD192: ul | AE192: rockroll | AF192: 35 | AG192: #N/A | AH192: 20
C193: 3 | D193: b | E193: experiment | F193: 3 | G193: CE.LIQ.FLOW.062 | H193: 44165 | I193: Sergio Reijnders - Ellis Herder | J193: 68 | K193: hour | L193: 50 | N193: 91-20-3 | O193: =VLOOKUP(Table3[[#This Row],[compCASRN]],expLookup!S:T,2,FALSE) -> naphthalene | P193: 19.5 | Q193: nM | R193: Liquid | S193: controlVehicleA | T193: N2 | U193: 25 | V193: OP50 | W193: heated | X193: 0.743 | Y193: 8 | Z193: 300 | AA193: ul | AB193: 1,5 glass vial | AC193: 1000 | AD193: ul | AE193: rockroll | AF193: 35 | AG193: #N/A | AH193: 20
C194: 3 | D194: c | E194: experiment | F194: 3 | G194: CE.LIQ.FLOW.062 | H194: 44165 | I194: Sergio Reijnders - Ellis Herder | J194: 68 | K194: hour | L194: 50 | N194: 91-20-3 | O194: =VLOOKUP(Table3[[#This Row],[compCASRN]],expLookup!S:T,2,FALSE) -> naphthalene | P194: 19.5 | Q194: nM | R194: Liquid | S194: controlVehicleA | T194: N2 | U194: 25 | V194: OP50 | W194: heated | X194: 0.743 | Y194: 8 | Z194: 300 | AA194: ul | AB194: 1,5 glass vial | AC194: 1000 | AD194: ul | AE194: rockroll | AF194: 35 | AG194: #N/A | AH194: 20
C195: 3 | D195: d | E195: experiment | F195: 3 | G195: CE.LIQ.FLOW.062 | H195: 44165 | I195: Sergio Reijnders - Ellis Herder | J195: 68 | K195: hour | L195: 50 | N195: 91-20-3 | O195: =VLOOKUP(Table3[[#This Row],[compCASRN]],expLookup!S:T,2,FALSE) -> naphthalene | P195: 19.5 | Q195: nM | R195: Liquid | S195: controlVehicleA | T195: N2 | U195: 25 | V195: OP50 | W195: heated | X195: 0.743 | Y195: 8 | Z195: 300 | AA195: ul | AB195: 1,5 glass vial | AC195: 1000 | AD195: ul | AE195: rockroll | AF195: 35 | AG195: #N/A | AH195: 20
C196: 3 | D196: e | E196: experiment | F196: 3 | G196: CE.LIQ.FLOW.062 | H196: 44165 | I196: Sergio Reijnders - Ellis Herder | J196: 68 | K196: hour | L196: 50 | N196: 91-20-3 | O196: =VLOOKUP(Table3[[#This Row],[compCASRN]],expLookup!S:T,2,FALSE) -> naphthalene | P196: 19.5 | Q196: nM | R196: Liquid | S196: controlVehicleA | T196: N2 | U196: 25 | V196: OP50 | W196: heated | X196: 0.743 | Y196: 8 | Z196: 300 | AA196: ul | AB196: 1,5 glass vial | AC196: 1000 | AD196: ul | AE196: rockroll | AF196: 35 | AG196: #N/A | AH196: 20
C197: 1 | D197: a | E197: experiment | F197: 3 | G197: CE.LIQ.FLOW.062 | H197: 44165 | I197: Sergio Reijnders - Ellis Herder | J197: 68 | K197: hour | L197: 50 | M197: 67 | N197: 91-20-3 | O197: =VLOOKUP(Table3[[#This Row],[compCASRN]],expLookup!S:T,2,FALSE) -> naphthalene | P197: 1.95 | Q197: nM | R197: Liquid | S197: controlVehicleA | T197: N2 | U197: 25 | V197: OP50 | W197: heated | X197: 0.743 | Y197: 8 | Z197: 300 | AA197: ul | AB197: 1,5 glass vial | AC197: 1000 | AD197: ul | AE197: rockroll | AF197: 35 | AG197: #N/A | AH197: 20
C198: 1 | D198: b | E198: experiment | F198: 3 | G198: CE.LIQ.FLOW.062 | H198: 44165 | I198: Sergio Reijnders - Ellis Herder | J198: 68 | K198: hour | L198: 50 | M198: 69 | N198: 91-20-3 | O198: =VLOOKUP(Table3[[#This Row],[compCASRN]],expLookup!S:T,2,FALSE) -> naphthalene | P198: 1.95 | Q198: nM | R198: Liquid | S198: controlVehicleA | T198: N2 | U198: 25 | V198: OP50 | W198: heated | X198: 0.743 | Y198: 8 | Z198: 300 | AA198: ul | AB198: 1,5 glass vial | AC198: 1000 | AD198: ul | AE198: rockroll | AF198: 35 | AG198: #N/A | AH198: 20
C199: 1 | D199: c | E199: experiment | F199: 3 | G199: CE.LIQ.FLOW.062 | H199: 44165 | I199: Sergio Reijnders - Ellis Herder | J199: 68 | K199: hour | L199: 50 | M199: 64 | N199: 91-20-3 | O199: =VLOOKUP(Table3[[#This Row],[compCASRN]],expLookup!S:T,2,FALSE) -> naphthalene | P199: 1.95 | Q199: nM | R199: Liquid | S199: controlVehicleA | T199: N2 | U199: 25 | V199: OP50 | W199: heated | X199: 0.743 | Y199: 8 | Z199: 300 | AA199: ul | AB199: 1,5 glass vial | AC199: 1000 | AD199: ul | AE199: rockroll | AF199: 35 | AG199: #N/A | AH199: 20
C200: 1 | D200: d | E200: experiment | F200: 3 | G200: CE.LIQ.FLOW.062 | H200: 44165 | I200: Sergio Reijnders - Ellis Herder | J200: 68 | K200: hour | L200: 50 | M200: 45 | N200: 91-20-3 | O200: =VLOOKUP(Table3[[#This Row],[compCASRN]],expLookup!S:T,2,FALSE) -> naphthalene | P200: 1.95 | Q200: nM | R200: Liquid | S200: controlVehicleA | T200: N2 | U200: 25 | V200: OP50 | W200: heated | X200: 0.743 | Y200: 8 | Z200: 300 | AA200: ul | AB200: 1,5 glass vial | AC200: 1000 | AD200: ul | AE200: rockroll | AF200: 35 | AG200: #N/A | AH200: 20
C201: 1 | D201: e | E201: experiment | F201: 3 | G201: CE.LIQ.FLOW.062 | H201: 44165 | I201: Sergio Reijnders - Ellis Herder | J201: 68 | K201: hour | L201: 50 | M201: 53 | N201: 91-20-3 | O201: =VLOOKUP(Table3[[#This Row],[compCASRN]],expLookup!S:T,2,FALSE) -> naphthalene | P201: 1.95 | Q201: nM | R201: Liquid | S201: controlVehicleA | T201: N2 | U201: 25 | V201: OP50 | W201: heated | X201: 0.743 | Y201: 8 | Z201: 300 | AA201: ul | AB201: 1,5 glass vial | AC201: 1000 | AD201: ul | AE201: rockroll | AF201: 35 | AG201: #N/A | AH201: 20
C202: 2 | D202: a | E202: experiment | F202: 3 | G202: CE.LIQ.FLOW.062 | H202: 44165 | I202: Sergio Reijnders - Ellis Herder | J202: 68 | K202: hour | L202: 50 | M202: 78 | N202: 91-20-3 | O202: =VLOOKUP(Table3[[#This Row],[compCASRN]],expLookup!S:T,2,FALSE) -> naphthalene | P202: 1.95 | Q202: nM | R202: Liquid | S202: controlVehicleA | T202: N2 | U202: 25 | V202: OP50 | W202: heated | X202: 0.743 | Y202: 8 | Z202: 300 | AA202: ul | AB202: 1,5 glass vial | AC202: 1000 | AD202: ul | AE202: rockroll | AF202: 35 | AG202: #N/A | AH202: 20
C203: 2 | D203: b | E203: experiment | F203: 3 | G203: CE.LIQ.FLOW.062 | H203: 44165 | I203: Sergio Reijnders - Ellis Herder | J203: 68 | K203: hour | L203: 50 | M203: 74 | N203: 91-20-3 | O203: =VLOOKUP(Table3[[#This Row],[compCASRN]],expLookup!S:T,2,FALSE) -> naphthalene | P203: 1.95 | Q203: nM | R203: Liquid | S203: controlVehicleA | T203: N2 | U203: 25 | V203: OP50 | W203: heated | X203: 0.743 | Y203: 8 | Z203: 300 | AA203: ul | AB203: 1,5 glass vial | AC203: 1000 | AD203: ul | AE203: rockroll | AF203: 35 | AG203: #N/A | AH203: 20
C204: 2 | D204: c | E204: experiment | F204: 3 | G204: CE.LIQ.FLOW.062 | H204: 44165 | I204: Sergio Reijnders - Ellis Herder | J204: 68 | K204: hour | L204: 50 | M204: 72 | N204: 91-20-3 | O204: =VLOOKUP(Table3[[#This Row],[compCASRN]],expLookup!S:T,2,FALSE) -> naphthalene | P204: 1.95 | Q204: nM | R204: Liquid | S204: controlVehicleA | T204: N2 | U204: 25 | V204: OP50 | W204: heated | X204: 0.743 | Y204: 8 | Z204: 300 | AA204: ul | AB204: 1,5 glass vial | AC204: 1000 | AD204: ul | AE204: rockroll | AF204: 35 | AG204: #N/A | AH204: 20
C205: 2 | D205: d | E205: experiment | F205: 3 | G205: CE.LIQ.FLOW.062 | H205: 44165 | I205: Sergio Reijnders - Ellis Herder | J205: 68 | K205: hour | L205: 50 | M205: 58 | N205: 91-20-3 | O205: =VLOOKUP(Table3[[#This Row],[compCASRN]],expLookup!S:T,2,FALSE) -> naphthalene | P205: 1.95 | Q205: nM | R205: Liquid | S205: controlVehicleA | T205: N2 | U205: 25 | V205: OP50 | W205: heated | X205: 0.743 | Y205: 8 | Z205: 300 | AA205: ul | AB205: 1,5 glass vial | AC205: 1000 | AD205: ul | AE205: rockroll | AF205: 35 | AG205: #N/A | AH205: 20
C206: 2 | D206: e | E206: experiment | F206: 3 | G206: CE.LIQ.FLOW.062 | H206: 44165 | I206: Sergio Reijnders - Ellis Herder | J206: 68 | K206: hour | L206: 50 | M206: 60 | N206: 91-20-3 | O206: =VLOOKUP(Table3[[#This Row],[compCASRN]],expLookup!S:T,2,FALSE) -> naphthalene | P206: 1.95 | Q206: nM | R206: Liquid | S206: controlVehicleA | T206: N2 | U206: 25 | V206: OP50 | W206: heated | X206: 0.743 | Y206: 8 | Z206: 300 | AA206: ul | AB206: 1,5 glass vial | AC206: 1000 | AD206: ul | AE206: rockroll | AF206: 35 | AG206: #N/A | AH206: 20
C207: 3 | D207: a | E207: experiment | F207: 3 | G207: CE.LIQ.FLOW.062 | H207: 44165 | I207: Sergio Reijnders - Ellis Herder | J207: 68 | K207: hour | L207: 50 | M207: 59 | N207: 91-20-3 | O207: =VLOOKUP(Table3[[#This Row],[compCASRN]],expLookup!S:T,2,FALSE) -> naphthalene | P207: 1.95 | Q207: nM | R207: Liquid | S207: controlVehicleA | T207: N2 | U207: 25 | V207: OP50 | W207: heated | X207: 0.743 | Y207: 8 | Z207: 300 | AA207: ul | AB207: 1,5 glass vial | AC207: 1000 | AD207: ul | AE207: rockroll | AF207: 35 | AG207: #N/A | AH207: 20
C208: 3 | D208: b | E208: experiment | F208: 3 | G208: CE.LIQ.FLOW.062 | H208: 44165 | I208: Sergio Reijnders - Ellis Herder | J208: 68 | K208: hour | L208: 50 | M208: 53 | N208: 91-20-3 | O208: =VLOOKUP(Table3[[#This Row],[compCASRN]],expLookup!S:T,2,FALSE) -> naphthalene | P208: 1.95 | Q208: nM | R208: Liquid | S208: controlVehicleA | T208: N2 | U208: 25 | V208: OP50 | W208: heated | X208: 0.743 | Y208: 8 | Z208: 300 | AA208: ul | AB208: 1,5 glass vial | AC208: 1000 | AD208: ul | AE208: rockroll | AF208: 35 | AG208: #N/A | AH208: 20
... C259: 1 | D259: c | E259: experiment | F259: 3 | G259: CE.LIQ.FLOW.062 | H259: 44165 | I259: Sergio Reijnders - Ellis Herder | J259: 68 | K259: hour | L259: 50 | M259: 78 | N259: 91-20-3 | O259: =VLOOKUP(Table3[[#This Row],[compCASRN]],expLookup!S:T,2,FALSE) -> naphthalene | P259: 0.000195 | Q259: nM | R259: Liquid | S259: controlVehicleA | T259: N2 | U259: 25 | V259: OP50 | W259: heated | X259: 0.743 | Y259: 8 | Z259: 300 | AA259: ul | AB259: 1,5 glass vial | AC259: 1000 | AD259: ul | AE259: rockroll | AF259: 35 | AG259: #N/A | AH259: 20
C260: 1 | D260: d | E260: experiment | F260: 3 | G260: CE.LIQ.FLOW.062 | H260: 44165 | I260: Sergio Reijnders - Ellis Herder | J260: 68 | K260: hour | L260: 50 | M260: 70 | N260: 91-20-3 | O260: =VLOOKUP(Table3[[#This Row],[compCASRN]],expLookup!S:T,2,FALSE) -> naphthalene | P260: 0,000195 | Q260: nM | R260: Liquid | S260: controlVehicleA | T260: N2 | U260: 25 | V260: OP50 | W260: heated | X260: 0.743 | Y260: 8 | Z260: 300 | AA260: ul | AB260: 1,5 glass vial | AC260: 1000 | AD260: ul | AE260: rockroll | AF260: 35 | AG260: #N/A | AH260: 20
C261: 1 | D261: e | E261: experiment | F261: 3 | G261: CE.LIQ.FLOW.062 | H261: 44165 | I261: Sergio Reijnders - Ellis Herder | J261: 68 | K261: hour | L261: 50 | M261: 76 | N261: 91-20-3 | O261: =VLOOKUP(Table3[[#This Row],[compCASRN]],expLookup!S:T,2,FALSE) -> naphthalene | P261: 0.000195 | Q261: nM | R261: Liquid | S261: controlVehicleA | T261: N2 | U261: 25 | V261: OP50 | W261: heated | X261: 0.743 | Y261: 8 | Z261: 300 | AA261: ul | AB261: 1,5 glass vial | AC261: 1000 | AD261: ul | AE261: rockroll | AF261: 35 | AG261: #N/A | AH261: 20
C262: 2 | D262: a | E262: experiment | F262: 3 | G262: CE.LIQ.FLOW.062 | H262: 44165 | I262: Sergio Reijnders - Ellis Herder | J262: 68 | K262: hour | L262: 50 | M262: 67 | N262: 91-20-3 | O262: =VLOOKUP(Table3[[#This Row],[compCASRN]],expLookup!S:T,2,FALSE) -> naphthalene | P262: 0.000195 | Q262: nM | R262: Liquid | S262: controlVehicleA | T262: N2 | U262: 25 | V262: OP50 | W262: heated | X262: 0.743 | Y262: 8 | Z262: 300 | AA262: ul | AB262: 1,5 glass vial | AC262: 1000 | AD262: ul | AE262: rockroll | AF262: 35 | AG262: #N/A | AH262: 20
C263: 2 | D263: b | E263: experiment | F263: 3 | G263: CE.LIQ.FLOW.062 | H263: 44165 | I263: Sergio Reijnders - Ellis Herder | J263: 68 | K263: hour | L263: 50 | M263: 64 | N263: 91-20-3 | O263: =VLOOKUP(Table3[[#This Row],[compCASRN]],expLookup!S:T,2,FALSE) -> naphthalene | P263: 0.000195 | Q263: nM | R263: Liquid | S263: controlVehicleA | T263: N2 | U263: 25 | V263: OP50 | W263: heated | X263: 0.743 | Y263: 8 | Z263: 300 | AA263: ul | AB263: 1,5 glass vial | AC263: 1000 | AD263: ul | AE263: rockroll | AF263: 35 | AG263: #N/A | AH263: 20
C264: 2 | D264: c | E264: experiment | F264: 3 | G264: CE.LIQ.FLOW.062 | H264: 44165 | I264: Sergio Reijnders - Ellis Herder | J264: 68 | K264: hour | L264: 50 | M264: 92 | N264: 91-20-3 | O264: =VLOOKUP(Table3[[#This Row],[compCASRN]],expLookup!S:T,2,FALSE) -> naphthalene | P264: 0.000195 | Q264: nM | R264: Liquid | S264: controlVehicleA | T264: N2 | U264: 25 | V264: OP50 | W264: heated | X264: 0.743 | Y264: 8 | Z264: 300 | AA264: ul | AB264: 1,5 glass vial | AC264: 1000 | AD264: ul | AE264: rockroll | AF264: 35 | AG264: #N/A | AH264: 20
C265: 2 | D265: d | E265: experiment | F265: 3 | G265: CE.LIQ.FLOW.062 | H265: 44165 | I265: Sergio Reijnders - Ellis Herder | J265: 68 | K265: hour | L265: 50 | M265: 76 | N265: 91-20-3 | O265: =VLOOKUP(Table3[[#This Row],[compCASRN]],expLookup!S:T,2,FALSE) -> naphthalene | P265: 0.000195 | Q265: nM | R265: Liquid | S265: controlVehicleA | T265: N2 | U265: 25 | V265: OP50 | W265: heated | X265: 0.743 | Y265: 8 | Z265: 300 | AA265: ul | AB265: 1,5 glass vial | AC265: 1000 | AD265: ul | AE265: rockroll | AF265: 35 | AG265: #N/A | AH265: 20
C266: 2 | D266: e | E266: experiment | F266: 3 | G266: CE.LIQ.FLOW.062 | H266: 44165 | I266: Sergio Reijnders - Ellis Herder | J266: 68 | K266: hour | L266: 50 | M266: 67 | N266: 91-20-3 | O266: =VLOOKUP(Table3[[#This Row],[compCASRN]],expLookup!S:T,2,FALSE) -> naphthalene | P266: 0.000195 | Q266: nM | R266: Liquid | S266: controlVehicleA | T266: N2 | U266: 25 | V266: OP50 | W266: heated | X266: 0.743 | Y266: 8 | Z266: 300 | AA266: ul | AB266: 1,5 glass vial | AC266: 1000 | AD266: ul | AE266: rockroll | AF266: 35 | AG266: #N/A | AH266: 20
C267: 3 | D267: a | E267: experiment | F267: 3 | G267: CE.LIQ.FLOW.062 | H267: 44165 | I267: Sergio Reijnders - Ellis Herder | J267: 68 | K267: hour | L267: 50 | M267: 62 | N267: 91-20-3 | O267: =VLOOKUP(Table3[[#This Row],[compCASRN]],expLookup!S:T,2,FALSE) -> naphthalene | P267: 0.000195 | Q267: nM | R267: Liquid | S267: controlVehicleA | T267: N2 | U267: 25 | V267: OP50 | W267: heated | X267: 0.743 | Y267: 8 | Z267: 300 | AA267: ul | AB267: 1,5 glass vial | AC267: 1000 | AD267: ul | AE267: rockroll | AF267: 35 | AG267: #N/A | AH267: 20
...

Sheet expLookup
A1: plateRow | C1: plateColumn | E1: vialNr | G1: dropCode | I1: expType | K1: expReplicate | M1: expName | O1: expResearcher | Q1: expUnit | S1: compCASRN | T1: compName | V1: compUnit | X1: compDelivery | Y1: Description | AA1: compVehicle | AC1: elegansStrain | AD1: elegansGenotype | AF1: bacterialStrain | AH1: bacterialTreatment | AJ1: bacterialConcX | AL1: bacterialVolUnit | AN1: incubationVial | AP1: incubationUnit | AR1: incubationMethod | AT1: incubateO2 | AV1: incubateTemperature | AX1: TEST | AY1: TEST2
A2: #N/A | C2: #N/A | E2: #N/A | G2: a | I2: experiment | K2: 1 | O2: Nienke Stigter | Q2: hour | S2: 1908-03-8 | T2: U 10520A | V2: pct | X2: Disc | Y2: Supplied by Chiel | AA2: controlVehicleA | AC2: N2 | AD2: wild type | AF2: OP50 | AH2: alive | AJ2: 2 | AL2: ul | AN2: 1,5 glass vial | AP2: ul | AR2: rotate | AT2: bubble | AV2: 15 | AX2: 3
A3: A | C3: 1 | E3: 1 | G3: b | I3: controlNegative | K3: 2 | O3: Jesus Arellano | Q3: min | S3: 1916-08-1 | T3: 3,4-dimethoxy-5-hydroxybenzoic acid | V3: nM | X3: Liquid | AA3: controlVehicleB | AC3: TJ1060 | AD3: spe-9(hc88) I; rrf-3(b26) II. | AF3: HB101 | AH3: irradiated | AJ3: 4 | AL3: ml | AN3: 6-wells plastic | AP3: ml | AR3: shake | AT3: top off | AV3: 16 | AX3: 4
A4: B | C4: 2 | E4: 2 | G4: c | I4: controlPositive | K4: 3 | O4: Johanna Louter | S4: 1918-02-1 | T4: Picloram | V4: uM | X4: Agar | AA4: controlVehicleC | AF4: HB101 From L4 | AH4: heated | AJ4: 5 | AN4: 12-wells plastic | AR4: wobble | AT4: #N/A | AV4: 20 | AX4: 5
A5: C | C5: 3 | E5: 3 | G5: d | I5: controlVehicleA | K5: 4 | O5: Marjolein Wildwater | S5: 1918-11-2 | T5: 3,5-di-t-butyl-4-methylphenyl N-methylcarbamate | V5: mM | AA5: controlVehicleD | AJ5: 8 | AN5: 24-wells plastic | AR5: rockroll | AV5: 25 | AX5: 6
A6: D | C6: 4 | E6: 4 | G6: e | I6: controlVehicleB | K6: 5 | O6: Monique van der Voet | S6: 1919-02-4 | T6: 17 beta-(3-furyl)-5 beta,14 beta-androstane-3 beta,14 beta-diol | V6: M | AA6: controlNegative | AJ6: 10 | AN6: 48-wells plastic | AR6: rockroll-wobble | AV6: RT
A7: E | C7: 5 | E7: 5 | I7: controlVehicleC | K7: 6 | S7: 1927-04-4 | T7: 5-hydroxydopamine | V7: mg/L | AJ7: 16 | AN7: 96-wells plastic
A8: F | C8: 6 | E8: 6 | I8: controlVehicleD | K8: 7 | S8: 1932-04-3 | T8: dipiperidinoethane | V8: g/L | AJ8: 20
A9: G | C9: 7 | E9: 7 | K9: 8 | S9: 1950-04-5 | T9: Preparation F-11 | AJ9: 32
A10: H | C10: 8 | E10: 8 | K10: 9 | S10: 1950-08-9 | T10: thiodipin | AJ10: 64
C11: 9 | E11: 9 | K11: 10 | O11: Sergio Reijnders - Ellis Herder | S11: 1953-02-2 | T11: Tiopronin | AJ11: 100
C12: 10 | E12: 10 | O12: Amra Milasinovic | S12: 1956-06-5 | T12: 4-nitrophenyl propionate | AJ12: 200
C13: 11 | E13: 11 | O13: Özlem Göksu | S13: 1956-10-1 | T13: 4-nitrophenyloctanoate
C14: 12 | E14: 12 | O14: Anna van der Vaart | S14: 1956-11-2 | T14: 4-nitrophenyl laurate
E15: 13 | O15: Ireen Scheffers | S15: 1968-05-4 | T15: 3,3'-diindolylmethane
E16: 14 | O16: Bas Geerdink | S16: 1977-07-7 | T16: 11-(4-methyl-1-piperazinyl)-5H-dibenzo(b,e)(1,4)diazepine
E17: 15 | O17: Liesbeth van Diesen - Niek van Schaffelaar | S17: 1977-08-8 | T17: 2-chloro-11-(4-methyl-1-piperazinyl)-5H-dibenzo(b,e)(1,4)diazepine
E18: 16 | S18: 1977-10-2 | T18: Loxapine
E19: 17 | S19: 1977-11-3 | T19: perlapine
E20: 18 | S20: 1985-12-2 | T20: 4-bromophenylisothiocyanate
E21: 19 | S21: 1990-01-8 | T21: glaucarubolone
E22: 20 | S22: 2004-03-7 | T22: 6-methylpurine
E23: 21 | S23: 2004-04-8 | T23: angustmycin A
E24: 22 | S24: 2005-10-9 | T24: 6H-dibenzo-(b,d)-pyran-6-one
E25: 23 | S25: 2006-02-2 | T25: adenosine arabinose
E26: 24 | S26: 2010-06-2 | T26: phenthiazamine
E27: 25 | S27: 2026-08-6 | T27: 1,8-naphthalenedimethanol
E28: 26 | S28: 2028-12-8 | T28: tetrahydrophthalamic acid
E29: 27 | S29: 2055-12-1 | T29: methylanabasine
... E53: 51 | S53: 2229-07-4 | T53: methyl radical
S54: 2240-05-3 | T54: guanylyl(3'-5')uridine 3'-monophosphate
S55: 2257-09-2 | T55: phenethyl isothiocyanate
S56: 2260-08-4 | T56: acetiromate
S57: 2274-01-3 | T57: diethylacetylurea
S58: 2283-11-6 | T58: tris(diethylamino)phosphine
S59: 2296-08-4 | T59: 9-furfuryladenine
S60: 2303-01-7 | T60: 3-cresol purple
S61: 2304-08-7 | T61: thymidine 5'-4-nitrophenyl phosphate
S62: 2322-04-5 | T62: N-methyl-N-(1-phenylethyl)-2-propynylamine
S63: 2375-05-5 | T63: methyl phosphoethanolamine
...

Sheet changes
A5: v1d | B5: ExpParameters | C5: ADD column 'rawData'
B6: ExpLookup | C6: column 'expResearcher' | G6: add Sergio Reijnders / Ellis Herder | M6: Sergio Reijnders - Ellis Herder
A9: v1e | B9: ExpParameters | C9: ADD column 'dropCode'
A13: v2a | B13: ExpParameters | C13: column "compConcentration" | G13: delete data validation (numbers) and make it available for any values
B14: ExpLookup | C14: column "compCASnr' | G14: add THF/ETHANOL combination | M14: THF/ETH | N14: THF versus ETHANOL
A16: v2b | B16: ExpLookup | C16: column "compUnit" | G16: add mg/L and g/L
B17: ExpLookup | C17: column "compCASnr' | G17: add UVCB1 - UVCB 20 | M17: UVCB1 | N17: UVCB1
A19: v2c | B19: ExpLookup | C19: column "compCASnr' | G19: add UVCB W1 - UVCB W20 | M19: UVCB W1 | N19: UVCB W1
A20: CURRENT | G20: add Hexadecene | M20: 26952-14-7 | N20: Hexadecene

Sheet example input
A1: plateRow | C1: plateColumn | E1: vialNr | G1: expType | I1: expReplicate | K1: expName | M1: expResearcher | O1: expUnit | Q1: compCASRN | R1: compName | T1: compUnit | V1: compDelivery | W1: Description | Y1: compVehicle | AA1: elegansStrain | AB1: elegansGenotype | AD1: bacterialStrain | AF1: bacterialTreatment | AH1: bacterialConcX | AJ1: bacterialVolUnit | AL1: incubationVial | AN1: incubationUnit | AP1: incubationMethod | AR1: incubateO2 | AT1: incubateTemperature
A2: #N/A | C2: #N/A | E2: #N/A | G2: experiment | I2: 1 | K2: CE.LIQ.001 | M2: Nienke Stigter | O2: hour | Q2: 1908-03-8 | R2: U 10520A | T2: pct | V2: Disc | W2: Supplied by Chiel | Y2: controlVehicleA | AA2: N2 | AB2: wild type | AD2: HB101 | AF2: alive | AH2: 2 | AJ2: ul | AL2: 1.5 | AN2: ul | AP2: rotate | AR2: bubble | AT2: 15
A3: A | C3: 1 | E3: 1 | G3: controlNegative | I3: 2 | K3: CE.LIQ.002 | M3: Amra Milasinovic | O3: min | Q3: 1916-08-1 | R3: 3,4-dimethoxy-5-hydroxybenzoic acid | T3: nM | V3: Liquid | Y3: controlVehicleB | AA3: TJ1060 | AB3: spe-9(hc88) I; rrf-3(b26) II. | AD3: OP50 | AF3: irradiated | AH3: 4 | AJ3: ml | AN3: ml | AP3: shake | AR3: top off | AT3: 16
A4: B | C4: 2 | E4: 2 | G4: controlPositive | I4: 3 | K4: CE.LIQ.003 | M4: Johanna Louter | Q4: 1918-02-1 | R4: Picloram | T4: mM | V4: Agar | Y4: controlVehicleC | AF4: heated | AH4: 8 | AP4: wobble | AR4: #N/A | AT4: 20
A5: C | C5: 3 | E5: 3 | G5: controlVehicleA | I5: 4 | K5: CE.LIQ.004 | M5: Marjolein Wildwater | Q5: 1918-11-2 | R5: 3,5-di-t-butyl-4-methylphenyl N-methylcarbamate | T5: uM | Y5: controlVehicleD | AH5: 16 | AP5: wobble-rotate | AT5: 25
A6: D | C6: 4 | E6: 4 | G6: controlVehicleB | I6: 5 | K6: CE.LIQ.005 | M6: Monique van der Voet | Q6: 1919-02-4 | R6: 17 beta-(3-furyl)-5 beta,14 beta-androstane-3 beta,14 beta-diol | T6: M | AH6: 32 | AT6: RT
A7: E | C7: 5 | E7: 5 | G7: controlVehicleC | I7: 6 | K7: CE.LIQ.006 | M7: Jesus Arellano | Q7: 1927-04-4 | R7: 5-hydroxydopamine | AH7: 64
A8: F | C8: 6 | E8: 6 | G8: controlVehicleD | I8: 7 | K8: CE.LIQ.007 | Q8: 1932-04-3 | R8: dipiperidinoethane | AH8: 100
A9: G | C9: 7 | E9: 7 | I9: 8 | K9: CE.LIQ.008 | Q9: 1950-04-5 | R9: Preparation F-11 | AH9: 200
A10: H | C10: 8 | E10: 8 | I10: 9 | K10: CE.LIQ.009 | Q10: 1950-08-9 | R10: thiodipin
C11: 9 | E11: 9 | I11: 10 | K11: CE.LIQ.010 | Q11: 1953-02-2 | R11: Tiopronin
C12: 10 | E12: 10 | K12: CE.LIQ.011 | Q12: 1956-06-5 | R12: 4-nitrophenyl propionate
C13: 11 | E13: 11 | K13: CE.LIQ.012 | Q13: 1956-10-1 | R13: 4-nitrophenyloctanoate
C14: 12 | E14: 12 | K14: CE.LIQ.013 | Q14: 1956-11-2 | R14: 4-nitrophenyl laurate
E15: 13 | K15: CE.LIQ.014 | Q15: 1968-05-4 | R15: 3,3'-diindolylmethane
E16: 14 | K16: CE.LIQ.015 | Q16: 1977-07-7 | R16: 11-(4-methyl-1-piperazinyl)-5H-dibenzo(b,e)(1,4)diazepine
E17: 15 | K17: CE.LIQ.016 | Q17: 1977-08-8 | R17: 2-chloro-11-(4-methyl-1-piperazinyl)-5H-dibenzo(b,e)(1,4)diazepine
E18: 16 | K18: CE.LIQ.017 | Q18: 1977-10-2 | R18: Loxapine
E19: 17 | K19: CE.LIQ.018 | Q19: 1977-11-3 | R19: perlapine
E20: 18 | K20: CE.LIQ.019 | Q20: 1985-12-2 | R20: 4-bromophenylisothiocyanate
E21: 19 | K21: CE.LIQ.020 | Q21: 1990-01-8 | R21: glaucarubolone
E22: 20 | K22: CE.LIQ.021 | Q22: 2004-03-7 | R22: 6-methylpurine
E23: 21 | K23: CE.LIQ.022 | Q23: 2004-04-8 | R23: angustmycin A
E24: 22 | K24: CE.LIQ.023 | Q24: 2005-10-9 | R24: 6H-dibenzo-(b,d)-pyran-6-one
E25: 23 | K25: CE.LIQ.024 | Q25: 2006-02-2 | R25: adenosine arabinose
E26: 24 | K26: CE.LIQ.025 | Q26: 2010-06-2 | R26: phenthiazamine
... E53: 51 | K53: CE.LIQ.052 | Q53: 2229-07-4 | R53: methyl radical
K54: CE.LIQ.053 | Q54: 2240-05-3 | R54: guanylyl(3'-5')uridine 3'-monophosphate
K55: CE.LIQ.054 | Q55: 2257-09-2 | R55: phenethyl isothiocyanate
K56: CE.LIQ.055 | Q56: 2260-08-4 | R56: acetiromate
K57: CE.LIQ.056 | Q57: 2274-01-3 | R57: diethylacetylurea
K58: CE.LIQ.057 | Q58: 2283-11-6 | R58: tris(diethylamino)phosphine
K59: CE.LIQ.058 | Q59: 2296-08-4 | R59: 9-furfuryladenine
K60: CE.LIQ.059 | Q60: 2303-01-7 | R60: 3-cresol purple
K61: CE.LIQ.060 | Q61: 2304-08-7 | R61: thymidine 5'-4-nitrophenyl phosphate
K62: CE.LIQ.061 | Q62: 2322-04-5 | R62: N-methyl-N-(1-phenylethyl)-2-propynylamine
K63: CE.LIQ.062 | Q63: 2375-05-5 | R63: methyl phosphoethanolamine
K64: CE.LIQ.063 | Q64: 2375-06-6 | R64: methyl phosphorylcholine
K65: CE.LIQ.064 | Q65: 2425-06-1 | R65: captafol
... K1000: CE.LIQ.999 | Q1000: 100919-15-1 | R1000: beta-1,4-mannan
...
